2023-08-27 20:54:01,142 -  nornir.core -     INFO -        run() - Running task 'napalm_get' with args {'getters': ['get_facts']} on 2 hosts
2023-08-27 21:00:28,485 -  nornir.core -     INFO -        run() - Running task 'napalm_get' with args {'getters': ['get_facts']} on 2 hosts
2023-08-28 18:46:12,478 -  nornir.core -     INFO -        run() - Running task 'write_facts' with args {} on 2 hosts
2023-08-28 18:46:15,627 - nornir.core.task -    ERROR -      start() - Host 'nxos1': task 'napalm_get' failed with traceback:
Traceback (most recent call last):
  File "/usr/lib/python3/dist-packages/urllib3/connection.py", line 169, in _new_conn
    conn = connection.create_connection(
  File "/usr/lib/python3/dist-packages/urllib3/util/connection.py", line 96, in create_connection
    raise err
  File "/usr/lib/python3/dist-packages/urllib3/util/connection.py", line 86, in create_connection
    sock.connect(sa)
OSError: [Errno 113] No route to host

During handling of the above exception, another exception occurred:

Traceback (most recent call last):
  File "/usr/lib/python3/dist-packages/urllib3/connectionpool.py", line 699, in urlopen
    httplib_response = self._make_request(
  File "/usr/lib/python3/dist-packages/urllib3/connectionpool.py", line 382, in _make_request
    self._validate_conn(conn)
  File "/usr/lib/python3/dist-packages/urllib3/connectionpool.py", line 1012, in _validate_conn
    conn.connect()
  File "/usr/lib/python3/dist-packages/urllib3/connection.py", line 353, in connect
    conn = self._new_conn()
  File "/usr/lib/python3/dist-packages/urllib3/connection.py", line 181, in _new_conn
    raise NewConnectionError(
urllib3.exceptions.NewConnectionError: <urllib3.connection.HTTPSConnection object at 0x7f61d3f95f00>: Failed to establish a new connection: [Errno 113] No route to host

During handling of the above exception, another exception occurred:

Traceback (most recent call last):
  File "/usr/lib/python3/dist-packages/requests/adapters.py", line 439, in send
    resp = conn.urlopen(
  File "/usr/lib/python3/dist-packages/urllib3/connectionpool.py", line 755, in urlopen
    retries = retries.increment(
  File "/usr/lib/python3/dist-packages/urllib3/util/retry.py", line 574, in increment
    raise MaxRetryError(_pool, url, error or ResponseError(cause))
urllib3.exceptions.MaxRetryError: HTTPSConnectionPool(host='nxos1', port=443): Max retries exceeded with url: /ins (Caused by NewConnectionError('<urllib3.connection.HTTPSConnection object at 0x7f61d3f95f00>: Failed to establish a new connection: [Errno 113] No route to host'))

During handling of the above exception, another exception occurred:

Traceback (most recent call last):
  File "/home/reuben/.local/lib/python3.10/site-packages/napalm/nxapi_plumbing/api_client.py", line 95, in _send_request
    response = requests.post(
  File "/usr/lib/python3/dist-packages/requests/api.py", line 119, in post
    return request('post', url, data=data, json=json, **kwargs)
  File "/usr/lib/python3/dist-packages/requests/api.py", line 61, in request
    return session.request(method=method, url=url, **kwargs)
  File "/usr/lib/python3/dist-packages/requests/sessions.py", line 544, in request
    resp = self.send(prep, **send_kwargs)
  File "/usr/lib/python3/dist-packages/requests/sessions.py", line 657, in send
    r = adapter.send(request, **kwargs)
  File "/usr/lib/python3/dist-packages/requests/adapters.py", line 516, in send
    raise ConnectionError(e, request=request)
requests.exceptions.ConnectionError: HTTPSConnectionPool(host='nxos1', port=443): Max retries exceeded with url: /ins (Caused by NewConnectionError('<urllib3.connection.HTTPSConnection object at 0x7f61d3f95f00>: Failed to establish a new connection: [Errno 113] No route to host'))

During handling of the above exception, another exception occurred:

Traceback (most recent call last):
  File "/home/reuben/.local/lib/python3.10/site-packages/napalm/nxos/nxos.py", line 803, in open
    self._send_command("show hostname")
  File "/home/reuben/.local/lib/python3.10/site-packages/napalm/nxos/nxos.py", line 820, in _send_command
    return self.device.show(command, raw_text=raw_text)
  File "/home/reuben/.local/lib/python3.10/site-packages/napalm/nxapi_plumbing/device.py", line 70, in show
    result = self.show_list(commands, raw_text)
  File "/home/reuben/.local/lib/python3.10/site-packages/napalm/nxapi_plumbing/device.py", line 98, in show_list
    return self.api._nxapi_command(commands, method=cmd_method)
  File "/home/reuben/.local/lib/python3.10/site-packages/napalm/nxapi_plumbing/api_client.py", line 136, in _nxapi_command
    response = self._send_request(commands, method=method)
  File "/home/reuben/.local/lib/python3.10/site-packages/napalm/nxapi_plumbing/api_client.py", line 104, in _send_request
    raise NXAPIConnectionError(str(e))
napalm.nxapi_plumbing.errors.NXAPIConnectionError: HTTPSConnectionPool(host='nxos1', port=443): Max retries exceeded with url: /ins (Caused by NewConnectionError('<urllib3.connection.HTTPSConnection object at 0x7f61d3f95f00>: Failed to establish a new connection: [Errno 113] No route to host'))

During handling of the above exception, another exception occurred:

Traceback (most recent call last):
  File "/home/reuben/.local/lib/python3.10/site-packages/nornir/core/task.py", line 99, in start
    r = self.task(self, **self.params)
  File "/home/reuben/.local/lib/python3.10/site-packages/nornir_napalm/plugins/tasks/napalm_get.py", line 32, in napalm_get
    device = task.host.get_connection(CONNECTION_NAME, task.nornir.config)
  File "/home/reuben/.local/lib/python3.10/site-packages/nornir/core/inventory.py", line 494, in get_connection
    self.open_connection(
  File "/home/reuben/.local/lib/python3.10/site-packages/nornir/core/inventory.py", line 546, in open_connection
    conn_obj.open(
  File "/home/reuben/.local/lib/python3.10/site-packages/nornir_napalm/plugins/connections/__init__.py", line 57, in open
    connection.open()
  File "/home/reuben/.local/lib/python3.10/site-packages/napalm/nxos/nxos.py", line 806, in open
    raise ConnectionException("Cannot connect to {}".format(self.hostname))
napalm.base.exceptions.ConnectionException: Cannot connect to nxos1

2023-08-28 18:46:15,628 - nornir.core.task -    ERROR -      start() - Host 'nxos1': task 'write_facts' failed with traceback:
Traceback (most recent call last):
  File "/home/reuben/.local/lib/python3.10/site-packages/nornir/core/task.py", line 99, in start
    r = self.task(self, **self.params)
  File "/home/reuben/VENV/python_netauto/nornir/group_runbook.py", line 26, in write_facts
    task1_result = task.run(task=napalm_get, getters=["get_facts"])
  File "/home/reuben/.local/lib/python3.10/site-packages/nornir/core/task.py", line 174, in run
    raise NornirSubTaskError(task=run_task, result=r)
nornir.core.exceptions.NornirSubTaskError: Subtask: napalm_get (failed)


2023-08-28 19:00:21,890 -  nornir.core -     INFO -        run() - Running task 'write_facts' with args {} on 2 hosts
2023-08-28 19:10:22,584 -  nornir.core -     INFO -        run() - Running task 'write_facts' with args {} on 2 hosts
